Workbook
Name Print_Area: consolidé!$A$1:$S$83
Name Print_Area: Consultants!#REF!
Name Print_Area: 'Facturation Client'!$A$1:$M$50
Name Print_Area: 'Société A'!$A$1:$O$68
Name Print_Area: 'Société B'!$A$1:$O$69
Name Print_Area: 'Société C-1'!$A$1:$O$70
Name Print_Area: 'Société C-2'!$A$1:$O$36

Sheet Tableau de Bord
A1: TABLEAU DE BORD - SUIVI DE PROJET CONSORTIUM
A3: 1. SYNTHÈSE GLOBALE DU PROJET
A5: Budget Total Projet | B5: 6600000 | C5: (À renseigner)
A6: Total Facturé Client | B6: ='Facturation Client'!I50 -> 6249636.2
A7: Reste à Facturer (RAF) | B7: =B5-B6 -> 350363.77
A8: % Avancement Facturation | B8: =IF(B5=0,0,B6/B5) -> 0.94691458
A9: Total Heures Consommées | B9: =consolidé!D82 -> 57354.55 | C9: heures
A10: Total Dépenses | B10: =consolidé!O68 -> 68994.88
A12: 2. RÉCAPITULATIF PAR PROJET
A14: Projet | B14: Budget | C14: Facturé | D14: RAF | E14: % Avancement | F14: Heures Budget | G14: Heures Réalisées | H14: Heures RAF | I14: % Heures
A15: Projet A | B15: ='Facturation Client'!E4 -> 2510239.2 | C15: ='Facturation Client'!E50 -> 2430239.7 | D15: =B15-C15 -> 79999.507 | E15: =IF(B15=0,0,C15/B15) -> 0.96813072 | F15: 31500 | G15: ='Société A'!E69 -> 30652.15 | H15: =F15-G15 -> 847.85 | I15: =IF(F15=0,0,G15/F15) -> 0.97308413
A16: Projet B | B16: ='Facturation Client'!F4 -> 1309691.7 | C16: ='Facturation Client'!F50 -> 1265663.3 | D16: =B16-C16 -> 44028.437 | E16: =IF(B16=0,0,C16/B16) -> 0.96638259 | F16: 12450 | G16: ='Société B'!E70 -> 12146 | H16: =F16-G16 -> 304 | I16: =IF(F16=0,0,G16/F16) -> 0.97558233
A17: Projet C | B17: ='Facturation Client'!G4 -> 1303576.4 | C17: ='Facturation Client'!G50 -> 1261810.7 | D17: =B17-C17 -> 41765.657 | E17: =IF(B17=0,0,C17/B17) -> 0.96796071 | F17: 12100 | G17: ='Société B'!E70 -> 12146 | H17: =F17-G17 -> -46 | I17: =IF(F17=0,0,G17/F17) -> 1.0038017
A18: Projet D | B18: ='Facturation Client'!H4 -> 1332362.9 | C18: ='Facturation Client'!H50 -> 1291922.5 | D18: =B18-C18 -> 40440.367 | E18: =IF(B18=0,0,C18/B18) -> 0.96964763 | F18: 31250 | G18: ='Société A'!E69 -> 30652.15 | H18: =F18-G18 -> 597.85 | I18: =IF(F18=0,0,G18/F18) -> 0.9808688
A19: TOTAL | B19: =SUM(B15:B18) -> 6455870.2 | C19: =SUM(C15:C18) -> 6249636.2 | D19: =SUM(D15:D18) -> 206233.97 | E19: =IF(B19=0,0,C19/B19) -> 0.96805481 | F19: =SUM(F15:F18) -> 87300 | G19: =SUM(G15:G18) -> 85596.3 | H19: =SUM(H15:H18) -> 1703.7 | I19: =IF(F19=0,0,G19/F19) -> 0.98048454
A22: 3. RÉCAPITULATIF PAR SOCIÉTÉ
A24: Société | B24: Part Budget | C24: Honoraires Facturés | D24: Dépenses | E24: Total Coûts | F24: RAF Estimé | G24: % Avancement | H24: Heures Budget | I24: Heures Réalisées | J24: Heures RAF | K24: % Heures
A25: Société A | B25: 3250000 | C25: ='Société A'!I68 -> 2285817.9 | D25: ='Société A'!H68 -> 45519.14 | E25: =C25+D25 -> 2331337 | F25: =B25-E25 -> 918662.97 | G25: =IF(B25=0,0,E25/B25) -> 0.71733447 | H25: 43948.374 | I25: 39650 | J25: =H25-I25 -> 4298.3743 | K25: =IF(H25=0,0,I25/H25) -> 0.90219492
A26: Société B | B26: =B16 -> 1309691.7 | C26: ='Société B'!I69 -> 762524.29 | D26: ='Société B'!H69 -> 20480.56 | E26: =C26+D26 -> 783004.85 | F26: =B26-E26 -> 526686.85 | G26: =IF(B26=0,0,E26/B26) -> 0.59785433 | H26: 17710.406 | I26: 16554 | J26: =H26-I26 -> 1156.4065 | K26: =IF(H26=0,0,I26/H26) -> 0.93470469
A27: Société C-1 | B27: =B17 -> 1303576.4 | C27: ='Société C-1'!I70 -> 889034.68 | D27: ='Société C-1'!H70 -> 2631.18 | E27: =C27+D27 -> 891665.86 | F27: =B27-E27 -> 411910.54 | G27: =IF(B27=0,0,E27/B27) -> 0.68401504 | H27: 17627.712 | I27: 17023 | J27: =H27-I27 -> 604.71186 | K27: =IF(H27=0,0,I27/H27) -> 0.96569539
A28: Société C-2 | B28: 592602.1 | C28: ='Société C-2'!I36 -> 103413.73 | D28: ='Société C-2'!H36 -> 364 | E28: =C28+D28 -> 103777.73 | F28: =B28-E28 -> 488824.37 | G28: =IF(B28=0,0,E28/B28) -> 0.17512211 | H28: 8013.5074 | I28: 12369.3 | J28: =H28-I28 -> -4355.7926 | K28: =IF(H28=0,0,I28/H28) -> 1.5435563
A29: TOTAL | B29: =SUM(B25:B28) -> 6455870.2 | C29: =SUM(C25:C28) -> 4040790.6 | D29: =SUM(D25:D28) -> 68994.88 | E29: =SUM(E25:E28) -> 4109785.5 | F29: =SUM(F25:F28) -> 2346084.7 | G29: =IF(B29=0,0,E29/B29) -> 0.63659667 | H29: =SUM(H25:H28) -> 87300 | I29: =SUM(I25:I28) -> 85596.3 | J29: =SUM(J25:J28) -> 1703.7 | K29: =IF(H29=0,0,I29/H29) -> 0.98048454
A32: 4. MATRICE PROJETS x SOCIÉTÉS (Facturation)
A34: Projet \ Société | B34: Société A | C34: Société B | D34: Société C | E34: Total Projet | F34: % du Total
A35: Projet A | B35: ='Facturation Client'!E50*0.5 -> 1215119.8 | C35: ='Facturation Client'!E50*0.25 -> 607559.92 | D35: ='Facturation Client'!E50*0.25 -> 607559.92 | E35: =SUM(B35:D35) -> 2430239.7 | F35: =IF($E$39=0,0,E35/$E$39) -> 0.38886098
A36: Projet B | B36: ='Facturation Client'!F50*0.5 -> 632831.63 | C36: ='Facturation Client'!F50*0.25 -> 316415.82 | D36: ='Facturation Client'!F50*0.25 -> 316415.82 | E36: =SUM(B36:D36) -> 1265663.3 | F36: =IF($E$39=0,0,E36/$E$39) -> 0.20251791
A37: Projet C | B37: ='Facturation Client'!G50*0.5 -> 630905.37 | C37: ='Facturation Client'!G50*0.25 -> 315452.69 | D37: ='Facturation Client'!G50*0.25 -> 315452.69 | E37: =SUM(B37:D37) -> 1261810.7 | F37: =IF($E$39=0,0,E37/$E$39) -> 0.20190147
A38: Projet D | B38: ='Facturation Client'!H50*0.5 -> 645961.27 | C38: ='Facturation Client'!H50*0.25 -> 322980.63 | D38: ='Facturation Client'!H50*0.25 -> 322980.63 | E38: =SUM(B38:D38) -> 1291922.5 | F38: =IF($E$39=0,0,E38/$E$39) -> 0.20671964
A39: Total Société | B39: =SUM(B35:B38) -> 3124818.1 | C39: =SUM(C35:C38) -> 1562409.1 | D39: =SUM(D35:D38) -> 1562409.1 | E39: =SUM(E35:E38) -> 6249636.2 | F39: =SUM(F35:F38) -> 1
A40: % par Société | B40: =IF($E$39=0,0,B39/$E$39) -> 0.5 | C40: =IF($E$39=0,0,C39/$E$39) -> 0.25 | D40: =IF($E$39=0,0,D39/$E$39) -> 0.25 | E40: =SUM(B40:D40) -> 1
A43: 5. INDICATEURS CLÉS DE PERFORMANCE
A45: HEURES
A46: Heures Budget Total | B46: =F19 -> 87300 | C46: (À renseigner)
A47: Heures Réalisées Total | B47: =consolidé!D82 -> 57354.55
A48: Heures Restantes (RAF) | B48: =B46-B47 -> 29945.45
A49: % Heures Consommées | B49: =IF(B46=0,0,B47/B46) -> 0.65698225
A51: FINANCES
A52: Taux Horaire Moyen Réalisé | B52: =IF(B47=0,0,B6/B47) -> 108.96496 | C52: $/heure
A53: Ratio Honoraires/Budget | B53: =IF(B5=0,0,consolidé!N68/B5) -> 0.60178723
A54: Consultants Externes | B54: =consolidé!Q68 -> 450633.01
...

Sheet consolidé
B1: HONORAIRES SONT À UN TAUX DE 1.9
B2: Société C | E2: Société C | H2: Société B | K2: Société A | N2: totaux
A3: période | B3: Honoraires associés | C3: Honoraires employés | D3: DEP | E3: Honoraires associés | F3: Honoraires employés | G3: DEP | H3: Honoraires associés | I3: Honoraires employés | J3: DEP | K3: Honoraires associés | L3: Honoraires employés | M3: DEP | N3: HONOR | O3: DEP | P3: Facture au client | Q3: Consultants | R3: Ratio par période | S3: Profit
A4: 1er mai au 1 août 2020 | B4: =+'Société C-1'!F4 -> 0 | C4: =+'Société C-1'!G4 -> 25530.13 | D4: =+'Société C-1'!H4 -> 372.18 | E4: =+'Société C-2'!F4 -> 0 | F4: =+'Société C-2'!G4 -> 0 | G4: =+'Société C-2'!H4 -> 0 | H4: =+'Société B'!F4 -> 5218.75 | I4: =+'Société B'!G4 -> 22959.22 | J4: =+'Société B'!H4 -> 0 | K4: =+'Société A'!F4 -> 29893.75 | L4: =+'Société A'!G4 -> 15393.69 | M4: =+'Société A'!H4 -> 6075.25 | N4: =+B4+C4+E4+F4+H4+I4+K4+L4 -> 98995.54 | O4: =+D4+G4+M4+J4 -> 6447.43 | P4: =+'Facturation Client'!I5 -> 0 | Q4: 0 | R4: =(P4-O4-Q4)/(N4/1.9) -> -0.12374413 | S4: =+P4-N4-O4-Q4 -> -105442.97
A5: 44044 | B5: =+'Société C-1'!F5 -> 0 | C5: =+'Société C-1'!G5 -> 14942.08 | D5: =+'Société C-1'!H5 -> 131.5 | E5: =+'Société C-2'!F5 -> 1656.25 | F5: =+'Société C-2'!G5 -> 369.25 | G5: =+'Société C-2'!H5 -> 0 | H5: =+'Société B'!F5 -> 1062.5 | I5: =+'Société B'!G5 -> 18334.67 | J5: =+'Société B'!H5 -> 0 | K5: =+'Société A'!F5 -> 17850 | L5: =+'Société A'!G5 -> 15023.6 | M5: =+'Société A'!H5 -> 0 | N5: =+B5+C5+E5+F5+H5+I5+K5+L5 -> 69238.35 | O5: =+D5+G5+M5+J5 -> 131.5 | P5: =+'Facturation Client'!I6 -> 275812.61 | Q5: 0 | R5: =(P5-O5-Q5)/(N5/1.9) -> 7.5650865 | S5: =+P5-N5-O5-Q5 -> 206442.76
A6: 44075 | B6: =+'Société C-1'!F6 -> 437.5 | C6: =+'Société C-1'!G6 -> 44540.91 | D6: =+'Société C-1'!H6 -> 120.32 | E6: =+'Société C-2'!F6 -> 512.5 | F6: =+'Société C-2'!G6 -> 9144.25 | G6: =+'Société C-2'!H6 -> 200.35 | H6: =+'Société B'!F6 -> 1937.5 | I6: =+'Société B'!G6 -> 26068.52 | J6: =+'Société B'!H6 -> 3877.5 | K6: =+'Société A'!F6 -> 37762.5 | L6: =+'Société A'!G6 -> 34256.1 | M6: =+'Société A'!H6 -> 293.45 | N6: =+B6+C6+E6+F6+H6+I6+K6+L6 -> 154659.78 | O6: =+D6+G6+M6+J6 -> 4491.62 | P6: =+'Facturation Client'!I7 -> 245169.32 | Q6: 0 | R6: =(P6-O6-Q6)/(N6/1.9) -> 2.9567327 | S6: =+P6-N6-O6-Q6 -> 86017.92
A7: 44105 | B7: =+'Société C-1'!F7 -> 0 | C7: =+'Société C-1'!G7 -> 34001.71 | D7: =+'Société C-1'!H7 -> 157.65 | E7: =+'Société C-2'!F7 -> 256.25 | F7: =+'Société C-2'!G7 -> 10624.75 | G7: =+'Société C-2'!H7 -> 0 | H7: =+'Société B'!F7 -> 2031.25 | I7: =+'Société B'!G7 -> 35031.21 | J7: =+'Société B'!H7 -> 0 | K7: =+'Société A'!F7 -> 38250 | L7: =+'Société A'!G7 -> 38774.44 | M7: =+'Société A'!H7 -> 0 | N7: =+B7+C7+E7+F7+H7+I7+K7+L7 -> 158969.61 | O7: =+D7+G7+M7+J7 -> 157.65 | P7: =+'Facturation Client'!I8 -> 261771.33 | Q7: =387.5+1950 -> 2337.5 | R7: =(P7-O7-Q7)/(N7/1.9) -> 3.0988611 | S7: =+P7-N7-O7-Q7 -> 100306.57
A8: 44136 | B8: =+'Société C-1'!F8 -> 0 | C8: =+'Société C-1'!G8 -> 42751.38 | D8: =+'Société C-1'!H8 -> 0 | E8: =+'Société C-2'!F8 -> 381.25 | F8: =+'Société C-2'!G8 -> 11885.45 | G8: =+'Société C-2'!H8 -> 0 | H8: =+'Société B'!F8 -> 1531.25 | I8: =+'Société B'!G8 -> 31719.51 | J8: =+'Société B'!H8 -> 0 | K8: =+'Société A'!F8 -> 35681.25 | L8: =+'Société A'!G8 -> 34580.05 | M8: =+'Société A'!H8 -> 0 | N8: =+B8+C8+E8+F8+H8+I8+K8+L8 -> 158530.14 | O8: =+D8+G8+M8+J8 -> 0 | P8: =+'Facturation Client'!I9 -> 318143.25 | Q8: =1540+1445+1760+5100+2390 -> 12235 | R8: =(P8-O8-Q8)/(N8/1.9) -> 3.6663418 | S8: =+P8-N8-O8-Q8 -> 147378.11
A9: 44166 | B9: =+'Société C-1'!F9 -> 312.5 | C9: =+'Société C-1'!G9 -> 33356.76 | D9: =+'Société C-1'!H9 -> 268.58 | E9: =+'Société C-2'!F9 -> 256.25 | F9: =+'Société C-2'!G9 -> 12697.04 | G9: =+'Société C-2'!H9 -> 0 | H9: =+'Société B'!F9 -> 2000 | I9: =+'Société B'!G9 -> 38933.39 | J9: =+'Société B'!H9 -> 0 | K9: =+'Société A'!F9 -> 28606.25 | L9: =+'Société A'!G9 -> 31501.67 | M9: =+'Société A'!H9 -> 178.9 | N9: =+B9+C9+E9+F9+H9+I9+K9+L9 -> 147663.86 | O9: =+D9+G9+M9+J9 -> 447.48 | P9: =+'Facturation Client'!I10 -> 254673.02 | Q9: =16812.5+7855+14775+8160+8790 -> 56392.5 | R9: =(P9-O9-Q9)/(N9/1.9) -> 2.5455299 | S9: =+P9-N9-O9-Q9 -> 50169.18
A10: 44197 | B10: =+'Société C-1'!F10 -> 0 | C10: =+'Société C-1'!G10 -> 48962.88 | D10: =+'Société C-1'!H10 -> 13 | E10: =+'Société C-2'!F10 -> 250 | F10: =+'Société C-2'!G10 -> 17698.5 | G10: =+'Société C-2'!H10 -> 0 | H10: =+'Société B'!F10 -> 1500 | I10: =+'Société B'!G10 -> 42429.39 | J10: =+'Société B'!H10 -> 0 | K10: =+'Société A'!F10 -> 32043.75 | L10: =+'Société A'!G10 -> 40191.3 | M10: =+'Société A'!H10 -> 0 | N10: =+B10+C10+E10+F10+H10+I10+K10+L10 -> 183075.82 | O10: =+D10+G10+M10+J10 -> 13 | P10: =+'Facturation Client'!I11 -> 961930 | Q10: =745+19315+5400+6900+7200+3600+6650+8450+16425+6100 -> 80785 | R10: =(P10-O10-Q10)/(N10/1.9) -> 9.1445763 | S10: =+P10-N10-O10-Q10 -> 698056.18
A11: 44228 | B11: =+'Société C-1'!F11 -> 125 | C11: =+'Société C-1'!G11 -> 53139.43 | D11: =+'Société C-1'!H11 -> 0 | E11: =+'Société C-2'!F11 -> 1150 | F11: =+'Société C-2'!G11 -> 16934.05 | G11: =+'Société C-2'!H11 -> 0 | H11: =+'Société B'!F11 -> 1406.25 | I11: =+'Société B'!G11 -> 37715.2 | J11: =+'Société B'!H11 -> 0 | K11: =+'Société A'!F11 -> 30793.75 | L11: =+'Société A'!G11 -> 58682.04 | M11: =+'Société A'!H11 -> 2117.25 | N11: =+B11+C11+E11+F11+H11+I11+K11+L11 -> 199945.72 | O11: =+D11+G11+M11+J11 -> 2117.25 | P11: =+'Facturation Client'!I12 -> 0 | Q11: =323.75+4430+1333+23211.25+6480 -> 35778 | R11: =(P11-O11-Q11)/(N11/1.9) -> -0.36010261 | S11: =+P11-N11-O11-Q11 -> -237840.97
A12: 44256 | B12: =+'Société C-1'!F12 -> 0 | C12: =+'Société C-1'!G12 -> 17723.03 | D12: =+'Société C-1'!H12 -> 0 | E12: =+'Société C-2'!F12 -> 0 | F12: =+'Société C-2'!G12 -> 19233.94 | G12: =+'Société C-2'!H12 -> 163.65 | H12: =+'Société B'!F12 -> 1125 | I12: =+'Société B'!G12 -> 33288.08 | J12: =+'Société B'!H12 -> 0 | K12: =+'Société A'!F12 -> 22350 | L12: =+'Société A'!G12 -> 61740.45 | M12: =+'Société A'!H12 -> 268.25 | N12: =+B12+C12+E12+F12+H12+I12+K12+L12 -> 155460.5 | O12: =+D12+G12+M12+J12 -> 431.9 | P12: =+'Facturation Client'!I13 -> 0 | Q12: =1138.75+15100+8625+1800+1800+1800 -> 30263.75 | R12: =(P12-O12-Q12)/(N12/1.9) -> -0.37515469 | S12: =+P12-N12-O12-Q12 -> -186156.15
A13: 44287 | B13: =+'Société C-1'!F13 -> 500 | C13: =+'Société C-1'!G13 -> 29209.98 | D13: =+'Société C-1'!H13 -> 0 | E13: =+'Société C-2'!F13 -> 0 | F13: =+'Société C-2'!G13 -> 0 | G13: =+'Société C-2'!H13 -> 0 | H13: =+'Société B'!F13 -> 1187.5 | I13: =+'Société B'!G13 -> 23508.68 | J13: =+'Société B'!H13 -> 0 | K13: =+'Société A'!F13 -> 17325 | L13: =+'Société A'!G13 -> 50371.35 | M13: =+'Société A'!H13 -> 73.93 | N13: =+B13+C13+E13+F13+H13+I13+K13+L13 -> 122102.51 | O13: =+D13+G13+M13+J13 -> 73.93 | P13: =+'Facturation Client'!I14 -> 0 | Q13: =2282.5+4230+3600+2700+1725 -> 14537.5 | R13: =(P13-O13-Q13)/(N13/1.9) -> -0.22736402 | S13: =+P13-N13-O13-Q13 -> -136713.94
A14: 44317 | B14: =+'Société C-1'!F14 -> 500 | C14: =+'Société C-1'!G14 -> 11109.31 | D14: =+'Société C-1'!H14 -> 0 | E14: =+'Société C-2'!F14 -> 0 | F14: =+'Société C-2'!G14 -> 0 | G14: =+'Société C-2'!H14 -> 0 | H14: =+'Société B'!F14 -> 656.25 | I14: =+'Société B'!G14 -> 15562.81 | J14: =+'Société B'!H14 -> 0 | K14: =+'Société A'!F14 -> 12037.5 | L14: =+'Société A'!G14 -> 22791.9 | M14: =+'Société A'!H14 -> 4.3 | N14: =+B14+C14+E14+F14+H14+I14+K14+L14 -> 62657.77 | O14: =+D14+G14+M14+J14 -> 4.3 | P14: =+'Facturation Client'!I15 -> 0 | Q14: =9750+3337.5+6105+2700+1800 -> 23692.5 | R14: =(P14-O14-Q14)/(N14/1.9) -> -0.71856882 | S14: =+P14-N14-O14-Q14 -> -86354.57
A15: 44348 | B15: =+'Société C-1'!F15 -> 500 | C15: =+'Société C-1'!G15 -> 5839.36 | D15: =+'Société C-1'!H15 -> 0 | E15: =+'Société C-2'!F15 -> 0 | F15: =+'Société C-2'!G15 -> 0 | G15: =+'Société C-2'!H15 -> 0 | H15: =+'Société B'!F15 -> 531.25 | I15: =+'Société B'!G15 -> 16538.39 | J15: =+'Société B'!H15 -> 0 | K15: =+'Société A'!F15 -> 10156.25 | L15: =+'Société A'!G15 -> 13574 | M15: =+'Société A'!H15 -> 0 | N15: =+B15+C15+E15+F15+H15+I15+K15+L15 -> 47139.25 | O15: =+D15+G15+M15+J15 -> 0 | P15: =+'Facturation Client'!I16 -> 0 | Q15: =416.25+885 -> 1301.25 | R15: =(P15-O15-Q15)/(N15/1.9) -> -0.052448331 | S15: =+P15-N15-O15-Q15 -> -48440.5
A16: 44378 | B16: =+'Société C-1'!F16 -> 375 | C16: =+'Société C-1'!G16 -> 769.98 | D16: =+'Société C-1'!H16 -> 0 | E16: =+'Société C-2'!F16 -> 0 | F16: =+'Société C-2'!G16 -> 0 | G16: =+'Société C-2'!H16 -> 0 | H16: =+'Société B'!F16 -> 250 | I16: =+'Société B'!G16 -> 6258.36 | J16: =+'Société B'!H16 -> 0 | K16: =+'Société A'!F16 -> 6575 | L16: =+'Société A'!G16 -> 5254.93 | M16: =+'Société A'!H16 -> 0 | N16: =+B16+C16+E16+F16+H16+I16+K16+L16 -> 19483.27 | O16: =+D16+G16+M16+J16 -> 0 | P16: =+'Facturation Client'!I17 -> 0 | Q16: 0 | R16: =(P16-O16-Q16)/(N16/1.9) -> 0 | S16: =+P16-N16-O16-Q16 -> -19483.27
A17: 44409 | B17: =+'Société C-1'!F17 -> 625 | C17: =+'Société C-1'!G17 -> 1253.53 | D17: =+'Société C-1'!H17 -> 0 | E17: =+'Société C-2'!F17 -> 0 | F17: =+'Société C-2'!G17 -> 0 | G17: =+'Société C-2'!H17 -> 0 | H17: =+'Société B'!F17 -> 656.25 | I17: =+'Société B'!G17 -> 9237.13 | J17: =+'Société B'!H17 -> 0 | K17: =+'Société A'!F17 -> 8306.25 | L17: =+'Société A'!G17 -> 6048.44 | M17: =+'Société A'!H17 -> 12.78 | N17: =+B17+C17+E17+F17+H17+I17+K17+L17 -> 26126.6 | O17: =+D17+G17+M17+J17 -> 12.78 | P17: =+'Facturation Client'!I18 -> 1357024.2 | Q17: 0 | R17: =(P17-O17-Q17)/(N17/1.9) -> 98.685699 | S17: =+P17-N17-O17-Q17 -> 1330884.9
A18: 44440 | B18: =+'Société C-1'!F18 -> 1050 | C18: =+'Société C-1'!G18 -> 2684.23 | D18: =+'Société C-1'!H18 -> 0 | E18: =+'Société C-2'!F18 -> 0 | F18: =+'Société C-2'!G18 -> 0 | G18: =+'Société C-2'!H18 -> 0 | H18: =+'Société B'!F18 -> 843.75 | I18: =+'Société B'!G18 -> 21648.31 | J18: =+'Société B'!H18 -> 0 | K18: =+'Société A'!F18 -> 7581.25 | L18: =+'Société A'!G18 -> 2957.12 | M18: =+'Société A'!H18 -> 8951.52 | N18: =+B18+C18+E18+F18+H18+I18+K18+L18 -> 36764.66 | O18: =+D18+G18+M18+J18 -> 8951.52 | P18: =+'Facturation Client'!I19 -> 0 | Q18: =1800+4506.25+1800 -> 8106.25 | R18: =(P18-O18-Q18)/(N18/1.9) -> -0.88154665 | S18: =+P18-N18-O18-Q18 -> -53822.43
A19: 44470 | B19: =+'Société C-1'!F19 -> 125 | C19: =+'Société C-1'!G19 -> 2210.25 | D19: =+'Société C-1'!H19 -> 0 | E19: =+'Société C-2'!F19 -> 0 | F19: =+'Société C-2'!G19 -> 0 | G19: =+'Société C-2'!H19 -> 0 | H19: =+'Société B'!F19 -> 375 | I19: =+'Société B'!G19 -> 15127.17 | J19: =+'Société B'!H19 -> 2200 | K19: =+'Société A'!F19 -> 9312.5 | L19: =+'Société A'!G19 -> 7748.85 | M19: =+'Société A'!H19 -> 0 | N19: =+B19+C19+E19+F19+H19+I19+K19+L19 -> 34898.77 | O19: =+D19+G19+M19+J19 -> 2200 | P19: =+'Facturation Client'!I20 -> 0 | Q19: 2112.5 | R19: =(P19-O19-Q19)/(N19/1.9) -> -0.23478621 | S19: =+P19-N19-O19-Q19 -> -39211.27
A20: 44501 | B20: =+'Société C-1'!F20 -> 406.25 | C20: =+'Société C-1'!G20 -> 6131.78 | D20: =+'Société C-1'!H20 -> 0 | E20: =+'Société C-2'!F20 -> 0 | F20: =+'Société C-2'!G20 -> 0 | G20: =+'Société C-2'!H20 -> 0 | H20: =+'Société B'!F20 -> 250 | I20: =+'Société B'!G20 -> 19539.79 | J20: =+'Société B'!H20 -> 796.33 | K20: =+'Société A'!F20 -> 6275 | L20: =+'Société A'!G20 -> 9770.41 | M20: =+'Société A'!H20 -> 217.02 | N20: =+B20+C20+E20+F20+H20+I20+K20+L20 -> 42373.23 | O20: =+D20+G20+M20+J20 -> 1013.35 | P20: =+'Facturation Client'!I21 -> 0 | Q20: =811.25+5850+2380+1380 -> 10421.25 | R20: =(P20-O20-Q20)/(N20/1.9) -> -0.51272325 | S20: =+P20-N20-O20-Q20 -> -53807.83
A21: 44531 | B21: =+'Société C-1'!F21 -> 650 | C21: =+'Société C-1'!G21 -> 2476.18 | D21: =+'Société C-1'!H21 -> 0 | E21: =+'Société C-2'!F21 -> 0 | F21: =+'Société C-2'!G21 -> 0 | G21: =+'Société C-2'!H21 -> 0 | H21: =+'Société B'!F21 -> 312.5 | I21: =+'Société B'!G21 -> 11737.82 | J21: =+'Société B'!H21 -> 102.02 | K21: =+'Société A'!F21 -> 8375 | L21: =+'Société A'!G21 -> 8953.71 | M21: =+'Société A'!H21 -> 544.5 | N21: =+B21+C21+E21+F21+H21+I21+K21+L21 -> 32505.21 | O21: =+D21+G21+M21+J21 -> 646.52 | P21: =+'Facturation Client'!I22 -> 0 | Q21: =33.75+1380+2112.5+690 -> 4216.25 | R21: =(P21-O21-Q21)/(N21/1.9) -> -0.28423945 | S21: =+P21-N21-O21-Q21 -> -37367.98
A22: 44562 | B22: =+'Société C-1'!F22 -> 562.5 | C22: =+'Société C-1'!G22 -> 6365.71 | D22: =+'Société C-1'!H22 -> 0 | E22: =+'Société C-2'!F22 -> 0 | F22: =+'Société C-2'!G22 -> 0 | G22: =+'Société C-2'!H22 -> 0 | H22: =+'Société B'!F22 -> 5562.5 | I22: =+'Société B'!G22 -> 19426.59 | J22: =+'Société B'!H22 -> 0 | K22: =+'Société A'!F22 -> 9868.75 | L22: =+'Société A'!G22 -> 20838.4 | M22: =+'Société A'!H22 -> 0 | N22: =+B22+C22+E22+F22+H22+I22+K22+L22 -> 62624.45 | O22: =+D22+G22+M22+J22 -> 0 | P22: =+'Facturation Client'!I23 -> 0 | Q22: 0 | R22: =(P22-O22-Q22)/(N22/1.9) -> 0 | S22: =+P22-N22-O22-Q22 -> -62624.45
A23: 44593 | B23: =+'Société C-1'!F23 -> 375 | C23: =+'Société C-1'!G23 -> 3627.81 | D23: =+'Société C-1'!H23 -> 0 | E23: =+'Société C-2'!F23 -> 0 | F23: =+'Société C-2'!G23 -> 0 | G23: =+'Société C-2'!H23 -> 0 | H23: =+'Société B'!F23 -> 6906.25 | I23: =+'Société B'!G23 -> 16083.96 | J23: =+'Société B'!H23 -> 575.59 | K23: =+'Société A'!F23 -> 11168.75 | L23: =+'Société A'!G23 -> 18785.17 | M23: =+'Société A'!H23 -> 72.68 | N23: =+B23+C23+E23+F23+H23+I23+K23+L23 -> 56946.94 | O23: =+D23+G23+M23+J23 -> 648.27 | P23: =+'Facturation Client'!I24 -> 0 | Q23: =370+165 -> 535 | R23: =(P23-O23-Q23)/(N23/1.9) -> -0.039479084 | S23: =+P23-N23-O23-Q23 -> -58130.21
A24: 44621 | B24: =+'Société C-1'!F24 -> 625 | C24: =+'Société C-1'!G24 -> 11736.55 | D24: =+'Société C-1'!H24 -> 0 | E24: =+'Société C-2'!F24 -> 0 | F24: =+'Société C-2'!G24 -> 0 | G24: =+'Société C-2'!H24 -> 0 | H24: =+'Société B'!F24 -> 6781.25 | I24: =+'Société B'!G24 -> 15492.15 | J24: =+'Société B'!H24 -> 961.73 | K24: =+'Société A'!F24 -> 15418.75 | L24: =+'Société A'!G24 -> 21282.25 | M24: =+'Société A'!H24 -> 951.98 | N24: =+B24+C24+E24+F24+H24+I24+K24+L24 -> 71335.95 | O24: =+D24+G24+M24+J24 -> 1913.71 | P24: 0 | Q24: =1380+2800+2800+3963.75 -> 10943.75 | R24: =(P24-O24-Q24)/(N24/1.9) -> -0.34245249 | S24: =+P24-N24-O24-Q24 -> -84193.41
A25: 44652 | B25: =+'Société C-1'!F25 -> 500 | C25: =+'Société C-1'!G25 -> 5064.21 | D25: =+'Société C-1'!H25 -> 0 | E25: =+'Société C-2'!F25 -> 0 | F25: =+'Société C-2'!G25 -> 0 | G25: =+'Société C-2'!H25 -> 0 | H25: =+'Société B'!F25 -> 8656.25 | I25: =+'Société B'!G25 -> 16137.52 | J25: =+'Société B'!H25 -> 0 | K25: =+'Société A'!F25 -> 6006.25 | L25: =+'Société A'!G25 -> 13686.47 | M25: =+'Société A'!H25 -> 99.76 | N25: =+B25+C25+E25+F25+H25+I25+K25+L25 -> 50050.7 | O25: =+D25+G25+M25+J25 -> 99.76 | P25: ='Facturation Client'!I25 -> 266654.75 | Q25: =165+1380 -> 1545 | R25: =(P25-O25-Q25)/(N25/1.9) -> 10.060179 | S25: =+P25-N25-O25-Q25 -> 214959.29
A26: 44682 | B26: =+'Société C-1'!F26 -> 1843.75 | C26: =+'Société C-1'!G26 -> 9453.23 | D26: =+'Société C-1'!H26 -> 0 | E26: =+'Société C-2'!F26 -> 0 | F26: =+'Société C-2'!G26 -> 0 | G26: =+'Société C-2'!H26 -> 0 | H26: =+'Société B'!F26 -> 7250 | I26: =+'Société B'!G26 -> 11534.19 | J26: =+'Société B'!H26 -> 0 | K26: =+'Société A'!F26 -> 9850 | L26: =+'Société A'!G26 -> 17671.24 | M26: =+'Société A'!H26 -> 165 | N26: =+B26+C26+E26+F26+H26+I26+K26+L26 -> 57602.41 | O26: =+D26+G26+M26+J26 -> 165 | P26: 0 | Q26: =185+3168.75+1800+1056.25 -> 6210 | R26: =(P26-O26-Q26)/(N26/1.9) -> -0.21027766 | S26: =+P26-N26-O26-Q26 -> -63977.41
A27: 44713 | B27: =+'Société C-1'!F27 -> 2937.5 | C27: =+'Société C-1'!G27 -> 11283.64 | D27: =+'Société C-1'!H27 -> 289.05 | E27: =+'Société C-2'!F27 -> 0 | F27: =+'Société C-2'!G27 -> 0 | G27: =+'Société C-2'!H27 -> 0 | H27: =+'Société B'!F27 -> 7625 | I27: =+'Société B'!G27 -> 9188.16 | J27: =+'Société B'!H27 -> 1670.16 | K27: =+'Société A'!F27 -> 7800 | L27: =+'Société A'!G27 -> 23076.1 | M27: =+'Société A'!H27 -> 2216.32 | N27: =+B27+C27+E27+F27+H27+I27+K27+L27 -> 61910.4 | O27: =+D27+G27+M27+J27 -> 4175.53 | P27: 0 | Q27: =Consultants!E125 -> 2907.5 | R27: =(P27-O27-Q27)/(N27/1.9) -> -0.21737474 | S27: =+P27-N27-O27-Q27 -> -68993.43
A28: 44743 | B28: =+'Société C-1'!F28 -> 375 | C28: =+'Société C-1'!G28 -> 5257.89 | D28: =+'Société C-1'!H28 -> 0 | E28: =+'Société C-2'!F28 -> 0 | F28: =+'Société C-2'!G28 -> 0 | G28: =+'Société C-2'!H28 -> 0 | H28: =+'Société B'!F28 -> 3906.25 | I28: =+'Société B'!G28 -> 5253.93 | J28: =+'Société B'!H28 -> 0 | K28: =+'Société A'!F28 -> 5550 | L28: =+'Société A'!G28 -> 16860.14 | M28: =+'Société A'!H28 -> 213.5 | N28: =+B28+C28+E28+F28+H28+I28+K28+L28 -> 37203.21 | O28: =+D28+G28+M28+J28 -> 213.5 | P28: 0 | Q28: =Consultants!E126 -> 1380 | R28: =(P28-O28-Q28)/(N28/1.9) -> -0.081381418 | S28: =+P28-N28-O28-Q28 -> -38796.71
A29: 44774 | B29: =+'Société C-1'!F29 -> 375 | C29: =+'Société C-1'!G29 -> 12629.26 | D29: =+'Société C-1'!H29 -> 88.92 | E29: 0 | F29: 0 | G29: 0 | H29: =+'Société B'!F29 -> 3250 | I29: =+'Société B'!G29 -> 5174.43 | J29: =+'Société B'!H29 -> 1149.81 | K29: =+'Société A'!F29 -> 8237.5 | L29: =+'Société A'!G29 -> 23749.06 | M29: =+'Société A'!H29 -> 1269.4 | N29: =+B29+C29+E29+F29+H29+I29+K29+L29 -> 53415.25 | O29: =+D29+G29+M29+J29 -> 2508.13 | P29: 0 | Q29: =+Consultants!E127+Consultants!E128+Consultants!E129 -> 4506.25 | R29: =(P29-O29-Q29)/(N29/1.9) -> -0.24950406 | S29: =+P29-N29-O29-Q29 -> -60429.63
A30: 44805 | B30: =+'Société C-1'!F30 -> 687.5 | C30: =+'Société C-1'!G30 -> 10464.26 | D30: =+'Société C-1'!H30 -> 156.65 | E30: 0 | F30: 0 | G30: 0 | H30: =+'Société B'!F30 -> 4847.5 | I30: =+'Société B'!G30 -> 10878.93 | J30: =+'Société B'!H30 -> 1534.35 | K30: =+'Société A'!F30 -> 9925 | L30: =+'Société A'!G30 -> 22746.09 | M30: =+'Société A'!H30 -> 539.99 | N30: =+B30+C30+E30+F30+H30+I30+K30+L30 -> 59549.28 | O30: =+D30+G30+M30+J30 -> 2230.99 | P30: 0 | Q30: =+Consultants!E9+Consultants!E130 -> 4380 | R30: =(P30-O30-Q30)/(N30/1.9) -> -0.21093254 | S30: =+P30-N30-O30-Q30 -> -66160.27
A31: 44835 | B31: =+'Société C-1'!F31 -> 625 | C31: =+'Société C-1'!G31 -> 6067.18 | D31: =+'Société C-1'!H31 -> 0 | E31: 0 | F31: 0 | G31: 0 | H31: =+'Société B'!F31 -> 3511.25 | I31: =+'Société B'!G31 -> 6871.19 | J31: =+'Société B'!H31 -> 1797 | K31: =+'Société A'!F31 -> 13993.75 | L31: =+'Société A'!G31 -> 22905.71 | M31: =+'Société A'!H31 -> 401 | N31: =+B31+C31+E31+F31+H31+I31+K31+L31 -> 53974.08 | O31: =+D31+G31+M31+J31 -> 2198 | P31: ='Facturation Client'!I26 -> 481430.18 | Q31: =+Consultants!E10+Consultants!E131 -> 1026.25 | R31: =(P31-O31-Q31)/(N31/1.9) -> 16.833844 | S31: =+P31-N31-O31-Q31 -> 424231.85
A32: 44866 | B32: =+'Société C-1'!F32 -> 525 | C32: =+'Société C-1'!G32 -> 4507.28 | D32: =+'Société C-1'!H32 -> 0 | E32: 0 | F32: 0 | G32: 0 | H32: =+'Société B'!F32+'Société B'!F33 -> 8891.25 | I32: =+'Société B'!G32+'Société B'!G33 -> 8163.8 | J32: =+'Société B'!H32+'Société B'!H33 -> 2106.14 | K32: =+'Société A'!F32 -> 16493.75 | L32: =+'Société A'!G32 -> 23602.75 | M32: =+'Société A'!H32 -> 433 | N32: =+B32+C32+E32+F32+H32+I32+K32+L32 -> 62183.83 | O32: =+D32+G32+M32+J32 -> 2539.14 | P32: 0 | Q32: =+Consultants!E11+Consultants!E12+Consultants!E132+Consultants!E133+Consultants!E134 -> 13417.5 | R32: =(P32-O32-Q32)/(N32/1.9) -> -0.48754823 | S32: =+P32-N32-O32-Q32 -> -78140.47
A33: 44896 | B33: =+'Société C-1'!F33+'Société C-1'!F39 -> 687.5 | C33: =+'Société C-1'!G33+'Société C-1'!G39 -> 102561.73 | D33: =+'Société C-1'!H33+'Société C-1'!H39 -> 0 | E33: 0 | F33: 0 | G33: 0 | H33: ='Société B'!F34 -> 3125 | I33: ='Société B'!G34 -> 3752.73 | J33: ='Société B'!H34 -> 106.39 | K33: =+'Société A'!F33 -> 17868.75 | L33: =+'Société A'!G33 -> 23507.04 | M33: =+'Société A'!H33 -> 275 | N33: =+B33+C33+E33+F33+H33+I33+K33+L33 -> 151502.75 | O33: =+D33+G33+M33+J33 -> 381.39 | P33: =+'Facturation Client'!I27 -> 116846.91 | Q33: =Consultants!E135+Consultants!E136+Consultants!E13 -> 3041.25 | R33: =(P33-O33-Q33)/(N33/1.9) -> 1.4224568 | S33: =+P33-N33-O33-Q33 -> -38078.48
A34: 44927 | B34: =+'Société C-1'!F34 -> 500 | C34: =+'Société C-1'!G34 -> 2971.13 | D34: =+'Société C-1'!H34 -> 0 | E34: 0 | F34: 0 | G34: 0 | H34: ='Société B'!F35 -> 2906.25 | I34: ='Société B'!G35 -> 4801.78 | J34: ='Société B'!H35 -> 510.86 | K34: =+'Société A'!F34 -> 12825 | L34: =+'Société A'!G34 -> 20976.49 | M34: =+'Société A'!H34 -> 275 | N34: =+B34+C34+E34+F34+H34+I34+K34+L34 -> 44980.65 | O34: =+D34+G34+M34+J34 -> 785.86 | P34: 0 | Q34: =+Consultants!E14+Consultants!E54+Consultants!E137+Consultants!E138 -> 17260 | R34: =(P34-O34-Q34)/(N34/1.9) -> -0.76226408 | S34: =+P34-N34-O34-Q34 -> -63026.51
A35: 44958 | B35: =+'Société C-1'!F35 -> 625 | C35: =+'Société C-1'!G35 -> 6775.78 | D35: =+'Société C-1'!H35 -> 0 | E35: 0 | F35: 0 | G35: 0 | H35: ='Société B'!F36 -> 4281.25 | I35: ='Société B'!G36 -> 5131.9 | J35: ='Société B'!H36 -> 212.78 | K35: =+'Société A'!F35 -> 15775 | L35: =+'Société A'!G35 -> 31779.42 | M35: =+'Société A'!H35 -> 395.5 | N35: =+B35+C35+E35+F35+H35+I35+K35+L35 -> 64368.35 | O35: =+D35+G35+M35+J35 -> 608.28 | P35: 0 | Q35: =+Consultants!E15 -> 370 | R35: =(P35-O35-Q35)/(N35/1.9) -> -0.02887649 | S35: =+P35-N35-O35-Q35 -> -65346.63
A36: 44986 | B36: =+'Société C-1'!F36 -> 812.5 | C36: =+'Société C-1'!G36 -> 14089.35 | D36: =+'Société C-1'!H36 -> 0 | E36: 0 | F36: 0 | G36: 0 | H36: ='Société B'!F37 -> 5406.25 | I36: ='Société B'!G37 -> 6601.08 | J36: ='Société B'!H37 -> 1317.1 | K36: =+'Société A'!F36 -> 28337.5 | L36: =+'Société A'!G36 -> 48812.44 | M36: =+'Société A'!H36 -> 2139.02 | N36: =+B36+C36+E36+F36+H36+I36+K36+L36 -> 104059.12 | O36: =+D36+G36+M36+J36 -> 3456.12 | P36: 0 | Q36: =+Consultants!E16 -> 416.25 | R36: =(P36-O36-Q36)/(N36/1.9) -> -0.070705028 | S36: =+P36-N36-O36-Q36 -> -107931.49
A37: 45017 | B37: =+'Société C-1'!F37 -> 500 | C37: =+'Société C-1'!G37 -> 6120.73 | D37: =+'Société C-1'!H37 -> 277.71 | E37: 0 | F37: 0 | G37: 0 | H37: ='Société B'!F38 -> 2937.5 | I37: ='Société B'!G38 -> 4256 | J37: ='Société B'!H38 -> 212.78 | K37: =+'Société A'!F37 -> 23762.5 | L37: =+'Société A'!G37 -> 31759.47 | M37: =+'Société A'!H37 -> 423.42 | N37: =+B37+C37+E37+F37+H37+I37+K37+L37 -> 69336.2 | O37: =+D37+G37+M37+J37 -> 913.91 | P37: 0 | Q37: =+Consultants!E162+Consultants!E163+Consultants!E17 -> 12727.5 | R37: =(P37-O37-Q37)/(N37/1.9) -> -0.37381165 | S37: =+P37-N37-O37-Q37 -> -82977.61
A38: 45047 | B38: =+'Société C-1'!F38+'Société C-1'!F40 -> 562.5 | C38: =+'Société C-1'!G38+'Société C-1'!G40 -> 149658.96 | D38: =+'Société C-1'!H38+'Société C-1'!H40 -> 88.4 | E38: 0 | F38: 0 | G38: 0 | H38: ='Société B'!F39 -> 3937.5 | I38: ='Société B'!G39 -> 3957.7 | J38: ='Société B'!H39 -> 809.85 | K38: =+'Société A'!F38 -> 24943.75 | L38: =+'Société A'!G38 -> 44593.97 | M38: =+'Société A'!H38 -> 1619.86 | N38: =+B38+C38+E38+F38+H38+I38+K38+L38 -> 227654.38 | O38: =+D38+G38+M38+J38 -> 2518.11 | P38: 0 | Q38: =+Consultants!E18+Consultants!E19 -> 4076.25 | R38: =(P38-O38-Q38)/(N38/1.9) -> -0.055036428 | S38: =+P38-N38-O38-Q38 -> -234248.74
A39: 45078 | B39: =+'Société C-1'!F41 -> 500 | C39: =+'Société C-1'!G41 -> 38035.31 | D39: =+'Société C-1'!H41 -> 339.5 | E39: 0 | F39: 0 | G39: 0 | H39: ='Société B'!F40 -> 1281.25 | I39: ='Société B'!G40 -> 1580.09 | J39: ='Société B'!H40 -> 116.29 | K39: =+'Société A'!F39 -> 21437.5 | L39: =+'Société A'!G39 -> 33114.64 | M39: =+'Société A'!H39 -> 705.42 | N39: =+B39+C39+E39+F39+H39+I39+K39+L39 -> 95948.79 | O39: =+D39+G39+M39+J39 -> 1161.21 | P39: 0 | Q39: =+Consultants!E20+Consultants!E139+Consultants!E140+Consultants!E141 -> 5212.5 | R39: =(P39-O39-Q39)/(N39/1.9) -> -0.12621367 | S39: =+P39-N39-O39-Q39 -> -102322.5
A40: 45108 | B40: =+'Société C-1'!F42 -> 562.5 | C40: =+'Société C-1'!G42 -> 5690.67 | D40: =+'Société C-1'!H42 -> 83.2 | E40: 0 | F40: 0 | G40: 0 | H40: ='Société B'!F41 -> 2062.5 | I40: ='Société B'!G41 -> 1415.5 | J40: ='Société B'!H41 -> 0 | K40: =+'Société A'!F40 -> 16943.75 | L40: =+'Société A'!G40 -> 30144.71 | M40: =+'Société A'!H40 -> 589.3 | N40: =+B40+C40+E40+F40+H40+I40+K40+L40 -> 56819.63 | O40: =+D40+G40+M40+J40 -> 672.5 | P40: =+'Facturation Client'!I28 -> 294994.74 | Q40: 0 | R40: =(P40-O40-Q40)/(N40/1.9) -> 9.8418849 | S40: =+P40-N40-O40-Q40 -> 237502.61
...

Sheet Facturation Client
A1: Facturation Société A | Société B | Société C
A3: Date | B3: Période | C3: Facture | D3: 001 - Conception | E3: Projet A | F3: Projet B | G3: Projet C | H3: Projet D | I3: Total avant taxes | J3: TPS 5% | K3: TVQ 9,975% | L3: Total | M3: Payé | N3: Solde dû
C4: Montant tâche | E4: 2510239.2 | F4: 1309691.7 | G4: 1303576.4 | H4: 1332362.9 | I4: =SUM(D4:H4) -> 6455870.2 | J4: =+I4*0.05 -> 322793.51 | K4: =+I4*0.09975 -> 643973.05 | L4: =+I4+J4+K4 -> 7422636.8
I5: =SUM(D5:H5) -> 0 | J5: =+I5*0.05 -> 0 | K5: =+I5*0.09975 -> 0 | L5: =+I5+J5+K5 -> 0
A6: 23-09-2020 | B6: Mai au 29 août 2020 | C6: 200117-1 | D6: 275812.61 | E6: =$D$6/4 -> 68953.152 | F6: =$D$6/4 -> 68953.152 | G6: =$D$6/4 -> 68953.152 | H6: =$D$6/4 -> 68953.152 | I6: =SUM(E6:H6) -> 275812.61 | J6: =+I6*0.05 -> 13790.63 | K6: =+I6*0.09975 -> 27512.308 | L6: =+I6+J6+K6 -> 317115.55 | M6: 317115.55 | N6: =L6-M6 -> 0
A7: 16-10-2020 | B7: 30 août au 3 octobre 2020 | C7: 200117-2 | D7: 245169.32 | E7: =$D$7/4 -> 61292.33 | F7: =$D$7/4 -> 61292.33 | G7: =$D$7/4 -> 61292.33 | H7: =$D$7/4 -> 61292.33 | I7: =SUM(E7:H7) -> 245169.32 | J7: =+I7*0.05 -> 12258.466 | K7: =+I7*0.09975 -> 24455.64 | L7: =+I7+J7+K7 -> 281883.43 | M7: 281883.43 | N7: =L7-M7 -> 0
A8: 12-11-2020 | B8: 4 au 31 octobre 2020 | C8: 200117-3 | D8: 261771.33 | E8: =$D$8/4 -> 65442.832 | F8: =$D$8/4 -> 65442.832 | G8: =$D$8/4 -> 65442.832 | H8: =$D$8/4 -> 65442.832 | I8: =SUM(E8:H8) -> 261771.33 | J8: =+I8*0.05 -> 13088.567 | K8: =+I8*0.09975 -> 26111.69 | L8: =+I8+J8+K8 -> 300971.59 | M8: 300971.59 | N8: =L8-M8 -> 0
A9: 08-12-2020 | B9: 1er au 28 novembre 2020 | C9: 200117-4 | D9: 318143.25 | E9: =$D$9/4 -> 79535.812 | F9: =$D$9/4 -> 79535.812 | G9: =$D$9/4 -> 79535.812 | H9: =$D$9/4 -> 79535.812 | I9: =SUM(E9:H9) -> 318143.25 | J9: =+I9*0.05 -> 15907.163 | K9: =+I9*0.09975 -> 31734.789 | L9: =+I9+J9+K9 -> 365785.2 | M9: 365785.2 | N9: =L9-M9 -> 0
A10: 20-01-2021 | B10: 29 nov au 2 janvier 2021 | C10: 200117-5 | D10: 254673.02 | E10: =$D$10/4 -> 63668.255 | F10: =$D$10/4 -> 63668.255 | G10: =$D$10/4 -> 63668.255 | H10: =$D$10/4 -> 63668.255 | I10: =SUM(E10:H10) -> 254673.02 | J10: =+I10*0.05 -> 12733.651 | K10: =+I10*0.09975 -> 25403.634 | L10: =+I10+J10+K10 -> 292810.3 | M10: 292810.3 | N10: =L10-M10 -> 0
A11: 16-02-2021 | B11: 3 au 30 janvier 2021 | C11: 200117-6 | D11: 961930 | E11: =$D$11/4 -> 240482.5 | F11: =$D$11/4 -> 240482.5 | G11: =$D$11/4 -> 240482.5 | H11: =$D$11/4 -> 240482.5 | I11: =SUM(E11:H11) -> 961930 | J11: =+I11*0.05 -> 48096.5 | K11: =+I11*0.09975 -> 95952.518 | L11: =+I11+J11+K11 -> 1105979 | M11: 1105979 | N11: =L11-M11 -> 0
I12: =SUM(E12:H12) -> 0 | J12: =+I12*0.05 -> 0 | K12: =+I12*0.09975 -> 0 | L12: =+I12+J12+K12 -> 0 | M12: 0 | N12: =L12-M12 -> 0
I13: =SUM(E13:H13) -> 0 | J13: =+I13*0.05 -> 0 | K13: =+I13*0.09975 -> 0 | L13: =+I13+J13+K13 -> 0 | M13: 0 | N13: =L13-M13 -> 0
I14: =SUM(E14:H14) -> 0 | J14: =+I14*0.05 -> 0 | K14: =+I14*0.09975 -> 0 | L14: =+I14+J14+K14 -> 0 | M14: 0 | N14: =L14-M14 -> 0
I15: =SUM(E15:H15) -> 0 | J15: =+I15*0.05 -> 0 | K15: =+I15*0.09975 -> 0 | L15: =+I15+J15+K15 -> 0 | M15: 0 | N15: =L15-M15 -> 0
I16: =SUM(E16:H16) -> 0 | J16: =+I16*0.05 -> 0 | K16: =+I16*0.09975 -> 0 | L16: =+I16+J16+K16 -> 0 | M16: 0 | N16: =L16-M16 -> 0
I17: =SUM(E17:H17) -> 0 | J17: =+I17*0.05 -> 0 | K17: =+I17*0.09975 -> 0 | L17: =+I17+J17+K17 -> 0 | M17: 0 | N17: =L17-M17 -> 0
A18: 01-09-2021 | B18: 1er février au 30 août 2021 | C18: 200117-7 | D18: 1357024.2 | E18: 1012723.4 | F18: 128058.62 | G18: 106302.62 | H18: 109939.62 | I18: =SUM(E18:H18) -> 1357024.2 | J18: =+I18*0.05 -> 67851.212 | K18: =+I18*0.09975 -> 135363.17 | L18: =+I18+J18+K18 -> 1560238.6 | M18: 1560238.6 | N18: =L18-M18 -> 0
I19: =SUM(E19:H19) -> 0 | J19: =+I19*0.05 -> 0 | K19: =+I19*0.09975 -> 0 | L19: =+I19+J19+K19 -> 0 | M19: 0 | N19: =L19-M19 -> 0
I20: =SUM(E20:H20) -> 0 | J20: =+I20*0.05 -> 0 | K20: =+I20*0.09975 -> 0 | L20: =+I20+J20+K20 -> 0 | M20: 0 | N20: =L20-M20 -> 0
I21: =SUM(E21:H21) -> 0 | J21: =+I21*0.05 -> 0 | K21: =+I21*0.09975 -> 0 | L21: =+I21+J21+K21 -> 0 | M21: 0 | N21: =L21-M21 -> 0
I22: =SUM(E22:H22) -> 0 | J22: =+I22*0.05 -> 0 | K22: =+I22*0.09975 -> 0 | L22: =+I22+J22+K22 -> 0 | M22: 0 | N22: =L22-M22 -> 0
I23: =SUM(E23:H23) -> 0 | J23: =+I23*0.05 -> 0 | K23: =+I23*0.09975 -> 0 | L23: =+I23+J23+K23 -> 0 | M23: 0 | N23: =L23-M23 -> 0
I24: =SUM(E24:H24) -> 0 | J24: =+I24*0.05 -> 0 | K24: =+I24*0.09975 -> 0 | L24: =+I24+J24+K24 -> 0 | M24: 0 | N24: =L24-M24 -> 0
A25: 26-05-2022 | B25: 31 août 2021 au 30 avril 2022 | C25: 200117-8 | D25: 266654.75 | E25: 90608.25 | F25: 0 | G25: 0 | H25: 176046.5 | I25: =SUM(E25:H25) -> 266654.75 | J25: =+I25*0.05 -> 13332.738 | K25: =+I25*0.09975 -> 26598.811 | L25: =+I25+J25+K25 -> 306586.3 | M25: 306586.3 | N25: =L25-M25 -> 0
A26: 14-11-2022 | B26: du 1er mai au 31 octobre 2022 | C26: 200117-9 | E26: 297922 | F26: 38169.74 | G26: 54335.78 | H26: 91002.66 | I26: =SUM(D26:H26) -> 481430.18 | J26: =+I26*0.05 -> 24071.509 | K26: =+I26*0.09975 -> 48022.66 | L26: =+I26+J26+K26 -> 553524.35 | M26: 553524.35 | N26: =L26-M26 -> 0
A27: 23-01-2023 | B27: du 1er novembre au 31 décembre 2022 | C27: 200117-10 | E27: 56206.77 | F27: 17862.62 | G27: 17732.14 | H27: 25045.38 | I27: =SUM(D27:H27) -> 116846.91 | J27: =+I27*0.05 -> 5842.3455 | K27: 11655.48 | L27: =+I27+J27+K27 -> 134344.74 | M27: 134344.74 | N27: =L27-M27 -> 0
A28: 30-09-2023 | B28: 1er janvier au 31 juillet 2023 | C28: 200117-11 | E28: 0 | F28: 93198.75 | G28: 145459.18 | H28: 56336.81 | I28: =SUM(D28:H28) -> 294994.74 | J28: =+I28*0.05 -> 14749.737 | K28: =+I28*0.09975-0.001 -> 29425.724 | L28: =+I28+J28+K28 -> 339170.2 | M28: 339170.2 | N28: =L28-M28 -> 0
A29: 26-10-2023 | B29: 1er août au 30 septembre 2023 | C29: 200117-12 | E29: 1161.88 | F29: 71870.32 | G29: 53014.9 | H29: 11778.29 | I29: =SUM(D29:H29) -> 137825.39 | J29: =+I29*0.05 -> 6891.2695 | K29: =+I29*0.09975 -> 13748.083 | L29: =+I29+J29+K29 -> 158464.74 | M29: 158464.74 | N29: =L29-M29 -> 0
A30: 31-12-2023 | B30: 1er octobre au 31 décembre 2023 | C30: 200117-13 | E30: 23181.1 | F30: 96689.75 | G30: 56400.1 | H30: 21429 | I30: =SUM(D30:H30) -> 197699.95 | J30: =+I30*0.05 -> 9884.9975 | K30: =+I30*0.09975 -> 19720.57 | L30: =+I30+J30+K30 -> 227305.52 | M30: 227305.52 | N30: =L30-M30 -> 0
A31: 10-05-2024 | B31: au 30 avril 2024 | C31: 200117-14 | E31: 5000 | F31: 38029.7 | G31: 57309.08 | H31: 14541.86 | I31: =SUM(D31:H31) -> 114880.64 | J31: =+I31*0.05 -> 5744.032 | K31: =+I31*0.09975 -> 11459.344 | L31: =+I31+J31+K31 -> 132084.02 | M31: 132084.02 | N31: =L31-M31 -> 0
A32: 18-09-2024 | B32: au 31 aout 2024 | C32: 200117-15 | E32: 359061.43 | F32: 189313.38 | G32: 179339.32 | H32: 184777.53 | I32: =SUM(D32:H32) -> 912491.66 | J32: =+I32*0.05 -> 45624.583 | K32: =+I32*0.09975 -> 91021.043 | L32: =+I32+J32+K32 -> 1049137.3 | M32: 1049137.3 | N32: =L32-M32 -> 0
A33: 18-10-2024 | B33: au 31 aout 2024 - dépenses | C33: 200117-16 | E33: 0 | F33: 2572.5 | G33: 756 | H33: 0 | I33: =SUM(D33:H33) -> 3328.5 | J33: =+I33*0.05 -> 166.425 | K33: =+I33*0.09975 -> 332.01788 | L33: =+I33+J33+K33 -> 3826.9429 | M33: 3826.9429 | N33: =L33-M33 -> 0
A34: 27-11-2024 | B34: au 30 novembre 2024 | C34: 200117-17 | E34: 5000 | F34: =6494-2500 -> 3994 | G34: =5181.44-2500 -> 2681.44 | H34: 7500 | I34: =SUM(D34:H34) -> 19175.44 | J34: =+I34*0.05 -> 958.772 | K34: =+I34*0.09975 -> 1912.7501 | L34: =+I34+J34+K34 -> 22046.962 | M34: 22046.962 | N34: =L34-M34 -> 0
B35: au 31 aout 2025 | C35: 200117-18 | E35: 0 | F35: 6529 | G35: 9105.3 | H35: 14150 | I35: =SUM(D35:H35) -> 29784.3 | J35: =+I35*0.05 -> 1489.215 | K35: =+I35*0.09975 -> 2970.9839 | L35: =+I35+J35+K35 -> 34244.499 | N35: =L35-M35 -> 34244.499
I36: =SUM(D36:H36) -> 0 | J36: =+I36*0.05 -> 0 | K36: =+I36*0.09975 -> 0 | L36: =+I36+J36+K36 -> 0 | M36: =+I36/2 -> 0 | N36: =L36-M36 -> 0
I37: =SUM(D37:H37) -> 0 | J37: =+I37*0.05 -> 0 | K37: =+I37*0.09975 -> 0 | L37: =+I37+J37+K37 -> 0 | M37: =+I37/2 -> 0 | N37: =L37-M37 -> 0
I38: =SUM(D38:H38) -> 0 | J38: =+I38*0.05 -> 0 | K38: =+I38*0.09975 -> 0 | L38: =+I38+J38+K38 -> 0 | M38: =+I38/2 -> 0 | N38: =L38-M38 -> 0
I39: =SUM(D39:H39) -> 0 | J39: =+I39*0.05 -> 0 | K39: =+I39*0.09975 -> 0 | L39: =+I39+J39+K39 -> 0 | M39: =+I39/2 -> 0 | N39: =L39-M39 -> 0
I40: =SUM(D40:H40) -> 0 | J40: =+I40*0.05 -> 0 | K40: =+I40*0.09975 -> 0 | L40: =+I40+J40+K40 -> 0 | M40: =+I40/2 -> 0 | N40: =L40-M40 -> 0
I41: =SUM(D41:H41) -> 0 | J41: =+I41*0.05 -> 0 | K41: =+I41*0.09975 -> 0 | L41: =+I41+J41+K41 -> 0 | M41: =+I41/2 -> 0 | N41: =L41-M41 -> 0
...

Sheet Société C-1
A1: Société C
A3: Date | B3: période | C3: facture | D3: Heures Associés | E3: Heures Employés | F3: Honoraires associés | G3: Honoraires employés | H3: Frais refacturables | I3: Sous-TOTAL | J3: TPS | K3: TVQ | L3: TOTAL | M3: payé | N3: dû | O3: Partage | P3: Coûtant Société C | Q3: Coûtant PRDI
A4: 44056 | B4: Mai à Juillet | C4: 36379 | D4: 0 | E4: 376.25 | F4: =D4*125 -> 0 | G4: 25530.13 | H4: 372.18 | I4: =SUM(F4:H4) -> 25902.31 | J4: =+I4*0.05 -> 1295.1155 | K4: =+I4*0.09975 -> 2583.7554 | L4: =SUM(I4:K4) -> 29781.181 | M4: 29781.181 | N4: =+L4-M4 -> 0
A5: 44075 | B5: Août | C5: 36511 | D5: 0 | E5: 244.5 | F5: =D5*125 -> 0 | G5: 14942.08 | H5: 131.5 | I5: =SUM(F5:H5) -> 15073.58 | J5: =+I5*0.05 -> 753.679 | K5: =+I5*0.09975 -> 1503.5896 | L5: =SUM(I5:K5) -> 17330.849 | M5: 17330.849 | N5: =+L5-M5 -> 0 | P5: 7864.25 | Q5: 0
A6: 44109 | B6: Septembre | C6: 36753 | D6: 3.5 | E6: 635.25 | F6: =D6*125 -> 437.5 | G6: =44978.41-F6 -> 44540.91 | H6: =120.32 -> 120.32 | I6: =SUM(F6:H6) -> 45098.73 | J6: =+I6*0.05 -> 2254.9365 | K6: =+I6*0.09975 -> 4498.5983 | L6: =SUM(I6:K6) -> 51852.265 | M6: 51852.265 | N6: =+L6-M6 -> 0 | O6: 18750 | P6: 22491.28 | Q6: 1287.81
A7: 44137 | B7: Octobre | C7: 37027 | D7: 0 | E7: 489.25 | F7: 0 | G7: 34001.71 | H7: =157.65 -> 157.65 | I7: =SUM(F7:H7) -> 34159.36 | J7: =+I7*0.05 -> 1707.968 | K7: =+I7*0.09975 -> 3407.3962 | L7: =SUM(I7:K7) -> 39274.724 | M7: 39274.724 | N7: =+L7-M7 -> 0 | P7: 17184.75 | Q7: 710.87
A8: 44166 | B8: Novembre | C8: 37288 | D8: 0 | E8: 611.75 | F8: 0 | G8: 42751.38 | I8: =SUM(F8:H8) -> 42751.38 | J8: =+I8*0.05 -> 2137.569 | K8: =+I8*0.09975 -> 4264.4502 | L8: =SUM(I8:K8) -> 49153.399 | M8: 49153.399 | N8: =+L8-M8 -> 0 | P8: 20202.75 | Q8: 2297.95
A9: 44202 | B9: décembre | C9: 37610 | D9: 2.5 | E9: =639.25-D9 -> 636.75 | F9: =2.5*125 -> 312.5 | G9: =33669.26-F9 -> 33356.76 | H9: =268.58 -> 268.58 | I9: =SUM(F9:H9) -> 33937.84 | J9: =+I9*0.05 -> 1696.892 | K9: =+I9*0.09975 -> 3385.2995 | L9: =SUM(I9:K9) -> 39020.032 | M9: 39020.032 | N9: =+L9-M9 -> 0 | P9: 16765.88 | Q9: =257.13+2112.01 -> 2369.14
A10: 44231 | B10: janvier | C10: 37894 | D10: 0 | E10: 613.75 | F10: 0 | G10: 48962.88 | H10: =9+4 -> 13 | I10: =SUM(F10:H10) -> 48975.88 | J10: =+I10*0.05 -> 2448.794 | K10: =+I10*0.09975 -> 4885.344 | L10: =SUM(I10:K10) -> 56310.018 | M10: 56310.018 | N10: =+L10-M10 -> 0 | P10: 25360.13 | Q10: 408.36
A11: 44257 | B11: février | C11: 38109 | D11: 1 | E11: =703-D11 -> 702 | F11: 125 | G11: =53264.43-F11 -> 53139.43 | I11: =SUM(F11:H11) -> 53264.43 | J11: =+I11*0.05 -> 2663.2215 | K11: =+I11*0.09975 -> 5313.1269 | L11: =SUM(I11:K11) -> 61240.778 | M11: 61240.778 | N11: =+L11-M11 -> 0 | O11: 81250 | P11: 24586.15 | Q11: 3477.98
A12: 44293 | B12: mars | C12: 38486 | D12: 0 | E12: 299.75 | F12: 0 | G12: 17723.03 | I12: =SUM(F12:H12) -> 17723.03 | J12: =+I12*0.05 -> 886.1515 | K12: =+I12*0.09975 -> 1767.8722 | L12: =SUM(I12:K12) -> 20377.054 | M12: 20377.054 | N12: =+L12-M12 -> 0 | P12: 9285.88 | Q12: 42.03
A13: 44319 | B13: avril | C13: 38647 | D13: 4 | E13: 492.25 | F13: 500 | G13: =29709.98-F13 -> 29209.98 | I13: =SUM(F13:H13) -> 29709.98 | J13: =+I13*0.05 -> 1485.499 | K13: =+I13*0.09975 -> 2963.5705 | L13: =SUM(I13:K13) -> 34159.05 | M13: 34159.05 | N13: =+L13-M13 -> 0 | P13: 11343.28 | Q13: 210.15
A14: 44349 | B14: mai | C14: 39182 | D14: 4 | E14: 179.5 | F14: 500 | G14: =11609.31-500 -> 11109.31 | I14: =SUM(F14:H14) -> 11609.31 | J14: =+I14*0.05 -> 580.4655 | K14: =+I14*0.09975 -> 1158.0287 | L14: =SUM(I14:K14)+0.01 -> 13347.814 | M14: 13347.814 | N14: =+L14-M14 -> 0 | P14: 6322.35 | Q14: 375.25
A15: 44378 | B15: juin | C15: PRAA-2021-0290 | D15: 4 | E15: =93.25+4 -> 97.25 | F15: 500 | G15: =6045.63-F15+293.73 -> 5839.36 | I15: =SUM(F15:H15) -> 6339.36 | J15: =+I15*0.05 -> 316.968 | K15: =+I15*0.09975 -> 632.35116 | L15: =SUM(I15:K15) -> 7288.6792 | M15: 7288.6792 | N15: =+L15-M15 -> 0 | P15: 3390.35 | Q15: 154.59
A16: 44414 | B16: juillet | C16: PRAA-2021-0560 | D16: 3 | E16: 12 | F16: 375 | G16: =1144.98-F16 -> 769.98 | I16: =SUM(F16:H16) -> 1144.98 | J16: =+I16*0.05 -> 57.249 | K16: =+I16*0.09975 -> 114.21176 | L16: =SUM(I16:K16) -> 1316.4408 | M16: 1316.4408 | N16: =+L16-M16 -> 0 | P16: 732.45 | Q16: 10.75
A17: 44448 | B17: Août | C17: PRAA-2021-0760 | D17: 5 | E17: =5.75+1+12.5 -> 19.25 | F17: 625 | G17: =1878.53-F17 -> 1253.53 | I17: =SUM(F17:H17) -> 1878.53 | J17: =+I17*0.05 -> 93.9265 | K17: =+I17*0.09975 -> 187.38337 | L17: =SUM(I17:K17) -> 2159.8399 | M17: 2159.8399 | N17: =+L17-M17 -> 0 | O17: 145500 | P17: 1756.75 | Q17: 10.75
A18: 44482 | B18: septembre | C18: PRAA-2021-0894 | D18: =6+2 -> 8 | E18: =1+0.5+7.5+9.75+20 -> 38.75 | F18: =750+300 -> 1050 | G18: =3734.23-F18 -> 2684.23 | I18: =SUM(F18:H18) -> 3734.23 | J18: =+I18*0.05 -> 186.7115 | K18: =+I18*0.09975 -> 372.48944 | L18: =SUM(I18:K18) -> 4293.4309 | M18: 4293.4309 | N18: =+L18-M18 -> 0 | P18: 2175.73 | Q18: 0
A19: 44503 | B19: Octobre | C19: PRAA-2021-1050 | D19: 2 | E19: =1+9+22 -> 32 | F19: 125 | G19: =2335.25-F19 -> 2210.25 | I19: =SUM(F19:H19) -> 2335.25 | J19: =+I19*0.05 -> 116.7625 | K19: =+I19*0.09975 -> 232.94119 | L19: =SUM(I19:K19) -> 2684.9537 | M19: 2684.9537 | N19: =+L19-M19 -> 0 | P19: 1317.28 | Q19: 0
A20: 44536 | B20: novembre | C20: PRAA-2021-1209 | D20: 3.25 | E20: =5.25+1+11 -> 17.25 | F20: 406.25 | G20: =6538.03-F20 -> 6131.78 | I20: =SUM(F20:H20) -> 6538.03 | J20: =+I20*0.05 -> 326.9015 | K20: =+I20*0.09975 -> 652.16849 | L20: =SUM(I20:K20) -> 7517.1 | M20: 7517.1 | N20: =+L20-M20 -> 0 | P20: 1994.64 | Q20: 0
A21: 44568 | B21: décembre | C21: PRAA-2022-0070 | D21: =4+1 -> 5 | E21: =11+4.5+4.25+1+11 -> 31.75 | F21: =500+150 -> 650 | G21: =3126.18-F21 -> 2476.18 | I21: =SUM(F21:H21) -> 3126.18 | J21: =+I21*0.05 -> 156.309 | K21: =+I21*0.09975-0.01 -> 311.82646 | L21: =SUM(I21:K21) -> 3594.3155 | M21: 3594.3155 | N21: =+L21-M21 -> 0
A22: 44610 | B22: 2 au 29 janvier 2022 | C22: PRAA-2022-0301 | D22: =4+0.5 -> 4.5 | E22: =62.5+9.75+17 -> 89.25 | F22: =500+62.5 -> 562.5 | G22: =6928.21-F22 -> 6365.71 | I22: =SUM(F22:H22) -> 6928.21 | J22: =+I22*0.05 -> 346.4105 | K22: =+I22*0.09975 -> 691.08895 | L22: =SUM(I22:K22) -> 7965.7094 | M22: 7965.7094 | N22: =+L22-M22 -> 0
A23: 44629 | B23: 30 janvier au 26 février 2022 | C23: PRAA-2022-0778 | D23: 3 | E23: =21+14.75+9.5+12 -> 57.25 | F23: 375 | G23: =4002.81-F23 -> 3627.81 | I23: =SUM(F23:H23) -> 4002.81 | J23: =+I23*0.05 -> 200.1405 | K23: =+I23*0.09975 -> 399.2803 | L23: =SUM(I23:K23) -> 4602.2308 | M23: 4602.2308 | N23: =+L23-M23 -> 0
A24: 44664 | B24: 27 février au 2 avril 2022 | C24: PRAA-2022-0781 | D24: 5 | E24: =68+6.25+0.5+104.75+18.5 -> 198 | F24: 625 | G24: =12361.55-F24 -> 11736.55 | I24: =SUM(F24:H24) -> 12361.55 | J24: =+I24*0.05 -> 618.0775 | K24: =+I24*0.09975 -> 1233.0646 | L24: =SUM(I24:K24) -> 14212.692 | M24: 14212.692 | N24: =+L24-M24 -> 0
A25: 44717 | B25: 3 au 30 avril 2022 | C25: PRAA-2022-0928 | D25: 4 | E25: =6.5+5.75+1+41+21 -> 75.25 | F25: 500 | G25: =5564.21-F25 -> 5064.21 | I25: =SUM(F25:H25) -> 5564.21 | J25: =+I25*0.05 -> 278.2105 | K25: =+I25*0.09975 -> 555.02995 | L25: =SUM(I25:K25) -> 6397.4504 | M25: 6397.4504 | N25: =+L25-M25 -> 0
A26: 44721 | B26: 1er au 28 mai 2022 | C26: PRAA-2022-1169 | D26: =4+10.75 -> 14.75 | E26: =7.25+33+4.5+2.5+58+0.5+28.5+4 -> 138.25 | F26: =500+1343.75 -> 1843.75 | G26: =11296.98-F26 -> 9453.23 | I26: =SUM(F26:H26) -> 11296.98 | J26: =+I26*0.05 -> 564.849 | K26: =+I26*0.09975 -> 1126.8738 | L26: =SUM(I26:K26) -> 12988.703 | M26: 12988.703 | N26: =+L26-M26 -> 0
A27: 44757 | B27: 29 mai au 2 juillet 2022 | C27: PRAA-2022-1351 | D27: =6.5+17 -> 23.5 | E27: 173.4 | F27: =812.5+2125 -> 2937.5 | G27: =14221.14-F27 -> 11283.64 | H27: 289.05 | I27: =SUM(F27:H27) -> 14510.19 | J27: 725.52 | K27: 1447.38 | L27: =SUM(I27:K27) -> 16683.09 | M27: 16683.09 | N27: =+L27-M27 -> 0
A28: 44803 | B28: 3 au 30 juillet 2022 | C28: PRAA-2022-1584 | D28: 3 | E28: =81.5-3 -> 78.5 | F28: 375 | G28: =5424.83-F28+208.06 -> 5257.89 | I28: =SUM(F28:H28) -> 5632.89 | J28: =+I28*0.05 -> 281.6445 | K28: 561.88 | L28: =SUM(I28:K28) -> 6476.4145 | M28: 6476.4145 | N28: =+L28-M28 -> 0
A29: 44826 | B29: 31 juillet au 3 septembre 2022 | C29: PRAA-2022-1717 | D29: 3 | E29: =175.25-D29+22.25 -> 194.5 | F29: 375 | G29: =12040.01-F29+964.25 -> 12629.26 | H29: 88.92 | I29: =SUM(F29:H29) -> 13093.18 | J29: =+I29*0.05 -> 654.659 | K29: =+I29*0.09975 -> 1306.0447 | L29: =SUM(I29:K29) -> 15053.884 | M29: 15053.884 | N29: =+L29-M29 -> 0
A30: 44841 | B30: 4 septembre au 1er octobre 202 | C30: PRAA-2022-1808 | D30: 5.5 | E30: =128.25-D30+28.75+11 -> 162.5 | F30: =625+62.5 -> 687.5 | G30: =9085.03-F30+2066.73 -> 10464.26 | H30: =81.16+75.49 -> 156.65 | I30: =SUM(F30:H30) -> 11308.41 | J30: =+I30*0.05 -> 565.4205 | K30: 1128.02 | L30: =SUM(I30:K30) -> 13001.851 | M30: 13001.851 | N30: =+L30-M30 -> 0
A31: 44871 | B31: 2 au 29 octobre 2022 | C31: PRAA-2022-1980 | D31: 5 | E31: =2.5+11.5+52+2.5+14+12 -> 94.5 | F31: 625 | G31: =6213.38-F31+478.8 -> 6067.18 | I31: =SUM(F31:H31) -> 6692.18 | J31: =+I31*0.05 -> 334.609 | K31: =+I31*0.09975 -> 667.54496 | L31: =SUM(I31:K31) -> 7694.334 | M31: 7694.334 | N31: =+L31-M31 -> 0
A32: 44898 | B32: 30 octobre au 26 novembre 2022 | C32: PRAA-2022-2205 | D32: 4 | E32: =12+1.5+43.5+6.75+4+3.5 -> 71.25 | F32: =375+150 -> 525 | G32: =4830.4-F32-14.25+216.13 -> 4507.28 | I32: =SUM(F32:H32) -> 5032.28 | J32: 251.62 | K32: =+I32*0.09975 -> 501.96993 | L32: =SUM(I32:K32) -> 5785.8699 | M32: 5785.8699 | N32: =+L32-M32 -> 0
A33: 44939 | B33: 27 novembre au 31 décembre 2022 | C33: PRAA-2023-0043 | D33: 5 | E33: =83.75-D33+8.25 -> 87 | F33: 625 | G33: =5599.2-F33+329.18 -> 5303.38 | I33: =SUM(F33:H33) -> 5928.38 | J33: 296.42 | K33: =+I33*0.09975 -> 591.35591 | L33: =SUM(I33:K33) -> 6816.1559 | M33: 6816.1559 | N33: =+L33-M33 -> 0
A34: 44967 | B34: 1er au 28 janvier 2023 | C34: PRAA-2023-0250 | D34: 4 | E34: =46.5-D34 -> 42.5 | F34: 500 | G34: =3471.13-F34 -> 2971.13 | I34: =SUM(F34:H34) -> 3471.13 | J34: =+I34*0.05 -> 173.5565 | K34: 346.24 | L34: =SUM(I34:K34) -> 3990.9265 | M34: 3990.9265 | N34: =+L34-M34 -> 0
A35: 45000 | B35: 29 janvier au 25 février 2023 | C35: PRAA-2023-0381 | D35: 5 | E35: =118.75-D35 -> 113.75 | F35: =+D35*125 -> 625 | G35: =7400.78-F35 -> 6775.78 | I35: =SUM(F35:H35) -> 7400.78 | J35: =+I35*0.05 -> 370.039 | K35: =+I35*0.09975 -> 738.2278 | L35: =SUM(I35:K35) -> 8509.0468 | M35: 8509.0468 | N35: =+L35-M35 -> 0
A36: 45026 | B36: 26 février au 1er avril 2023 | C36: PRAA-2023-0489 | D36: 6.5 | E36: =249.5-D36 -> 243 | F36: =+D36*125 -> 812.5 | G36: =14901.85-F36 -> 14089.35 | I36: =SUM(F36:H36) -> 14901.85 | J36: =+I36*0.05 -> 745.0925 | K36: =+I36*0.09975 -> 1486.4595 | L36: =SUM(I36:K36) -> 17133.402 | M36: 17133.402 | N36: =+L36-M36 -> 0
A37: 45072 | B37: 2 au 29 avril 2023 | C37: PRAA-2023-0718 | D37: 4 | E37: =99-D37+3 -> 98 | F37: =+D37*125 -> 500 | G37: =6445.93-F37+174.8 -> 6120.73 | H37: =100.48+172.96+9.7-5.43 -> 277.71 | I37: =SUM(F37:H37) -> 6898.44 | J37: =+I37*0.05+0.005 -> 344.927 | K37: =+I37*0.09975 -> 688.11939 | L37: =SUM(I37:K37) -> 7931.4864 | M37: 7931.4864 | N37: =+L37-M37 -> 0
A38: 45091 | B38: 30 avril au 3 juin 2023 | C38: PRAA-2023-0851 | D38: 4 | E38: =318.5-D38 -> 314.5 | F38: =+D38*125 -> 500 | G38: =20252.33-F38 -> 19752.33 | H38: 88.4 | I38: =SUM(F38:H38) -> 20340.73 | J38: =+I38*0.05 -> 1017.0365 | K38: =+I38*0.09975-0.005 -> 2028.9828 | L38: =SUM(I38:K38) -> 23386.749 | M38: 23386.749 | N38: =+L38-M38 -> 0
A39: 45163 | B39: Granby 2022 | C39: PRAA-2023-1262 | D39: 0.5 | E39: =1384.5-D39 -> 1384 | F39: =+D39*125 -> 62.5 | G39: =97320.85-F39 -> 97258.35 | I39: =SUM(F39:H39) -> 97320.85 | J39: =+I39*0.05 -> 4866.0425 | K39: =+I39*0.09975+0.001 -> 9707.7558 | L39: =SUM(I39:K39) -> 111894.65 | M39: 111894.65 | N39: =+L39-M39 -> 0
A40: 45163 | B40: Granby au 3 juin 2023 | C40: PRAA-2023-1259 | D40: 0.5 | E40: =1970-D40 -> 1969.5 | F40: =+D40*125 -> 62.5 | G40: =129969.13-F40 -> 129906.63 | I40: =SUM(F40:H40) -> 129969.13 | J40: =+I40*0.05 -> 6498.4565 | K40: =+I40*0.09975 -> 12964.421 | L40: =SUM(I40:K40) -> 149432.01 | M40: 149432.01 | N40: =+L40-M40 -> 0
A41: 45163 | B41: 4 juin au 1er juillet 2023 | C41: PRAA-2023-1260 | D41: 4 | E41: =552.5-D41 -> 548.5 | F41: =+D41*125 -> 500 | G41: =38535.31-F41 -> 38035.31 | H41: 339.5 | I41: =SUM(F41:H41) -> 38874.81 | J41: =+I41*0.05+0.005 -> 1943.7455 | K41: =+I41*0.09975 -> 3877.7623 | L41: =SUM(I41:K41) -> 44696.318 | M41: 44696.318 | N41: =+L41-M41 -> 0
...

Sheet Société C-2
A1: Société C
A3: Date | B3: période | C3: facture | D3: Heures Associés | E3: Heures Employés | F3: Honoraires associés | G3: Honoraires employés | H3: Frais refacturables | I3: Sous-TOTAL | J3: TPS | K3: TVQ | L3: TOTAL | M3: payé | N3: dû | O3: Partage
I4: =SUM(F4:H4) -> 0 | J4: =+I4*0.05 -> 0 | K4: =+I4*0.09975 -> 0 | L4: =SUM(I4:K4) -> 0 | M4: 0 | N4: =+L4-M4 -> 0 | O4: 0
B5: au 29 août 2020 | C5: P20-021-1 | D5: 13 | E5: 3.75 | F5: =187.5+1468.75 -> 1656.25 | G5: =2025.5-F5 -> 369.25 | I5: =SUM(F5:H5) -> 2025.5 | J5: =+I5*0.05 -> 101.275 | K5: =+I5*0.09975 -> 202.04363 | L5: =SUM(I5:K5) -> 2328.8186 | M5: 2328.8186 | N5: =+L5-M5 -> 0 | O5: 0
A6: 44109 | B6: au 3 octobre 2020 | C6: P20-021-2 | D6: 4 | E6: 136.5 | F6: 512.5 | G6: =9656.75-F6 -> 9144.25 | H6: 200.35 | I6: =SUM(F6:H6) -> 9857.1 | J6: =+I6*0.05 -> 492.855 | K6: =+I6*0.09975 -> 983.24573 | L6: =SUM(I6:K6) -> 11333.201 | M6: 11333.201 | N6: =+L6-M6 -> 0 | O6: 18750
A7: 44135 | B7: au 31 otobre 2020 | C7: P20-021-3 | D7: 2 | E7: =159-D7 -> 157 | F7: 256.25 | G7: =10881-F7 -> 10624.75 | I7: =SUM(F7:H7) -> 10881 | J7: =+I7*0.05 -> 544.05 | K7: =+I7*0.09975 -> 1085.3798 | L7: =SUM(I7:K7) -> 12510.43 | M7: 12510.43 | N7: =+L7-M7 -> 0
A8: 44167 | B8: au 28 novembre 2020 | C8: P20-021-4 | D8: 3 | E8: =185.5-D8 -> 182.5 | F8: =37.5+343.75 -> 381.25 | G8: =12266.7-F8 -> 11885.45 | I8: =SUM(F8:H8) -> 12266.7 | J8: =+I8*0.05 -> 613.335 | K8: =+I8*0.09975 -> 1223.6033 | L8: =SUM(I8:K8) -> 14103.638 | M8: 14103.638 | N8: =+L8-M8 -> 0
A9: 43841 | B9: au 2 janvier 2021 | C9: P20-021-5 | D9: 2 | E9: =220.75-D9 -> 218.75 | F9: 256.25 | G9: =12953.29-F9 -> 12697.04 | I9: =SUM(F9:H9) -> 12953.29 | J9: =+I9*0.05 -> 647.6645 | K9: =+I9*0.09975 -> 1292.0907 | L9: =SUM(I9:K9) -> 14893.045 | M9: 14893.045 | N9: =+L9-M9 -> 0
A10: 44242 | B10: au 30 janvier 2021 | C10: P20-021-6 | D10: 2 | E10: =290-D10 -> 288 | F10: 250 | G10: =17948.5-F10 -> 17698.5 | I10: =SUM(F10:H10) -> 17948.5 | J10: =+I10*0.05 -> 897.425 | K10: =+I10*0.09975 -> 1790.3629 | L10: =SUM(I10:K10) -> 20636.288 | M10: 20636.288 | N10: =+L10-M10 -> 0
A11: 44259 | B11: 31 janvier au 27 février 2021 | C11: P20-021-7 | D11: 9 | E11: =277-D11 -> 268 | F11: =150+1000 -> 1150 | G11: =18084.05-F11 -> 16934.05 | I11: =SUM(F11:H11) -> 18084.05 | J11: =+I11*0.05 -> 904.2025 | K11: =+I11*0.09975 -> 1803.884 | L11: =SUM(I11:K11)-0.01 -> 20792.126 | M11: 20792.126 | N11: =+L11-M11 -> 0 | O11: 81250
A12: 44294 | B12: 28 février au 3 avril 2021 | C12: P20-021-8 | D12: 0 | E12: 310.5 | F12: 0 | G12: 19233.94 | H12: 163.65 | I12: =SUM(F12:H12) -> 19397.59 | J12: =+I12*0.05 -> 969.8795 | K12: =+I12*0.09975 -> 1934.9096 | L12: =SUM(I12:K12) -> 22302.379 | M12: 22302.379 | N12: =+L12-M12 -> 0 | O12: 42000
I13: =SUM(F13:H13) -> 0 | J13: =+I13*0.05 -> 0 | K13: =+I13*0.09975 -> 0 | L13: =SUM(I13:K13) -> 0 | N13: =+L13-M13 -> 0
N14: =+L14-M14 -> 0
I15: =SUM(F15:H15) -> 0 | J15: =+I15*0.05 -> 0 | K15: =+I15*0.09975 -> 0 | L15: =SUM(I15:K15) -> 0 | N15: =+L15-M15 -> 0
I16: =SUM(F16:H16) -> 0 | J16: =+I16*0.05 -> 0 | K16: =+I16*0.09975 -> 0 | L16: =SUM(I16:K16) -> 0 | N16: =+L16-M16 -> 0
I17: =SUM(F17:H17) -> 0 | J17: =+I17*0.05 -> 0 | K17: =+I17*0.09975 -> 0 | L17: =SUM(I17:K17) -> 0 | N17: =+L17-M17 -> 0
I18: =SUM(F18:H18) -> 0 | J18: =+I18*0.05 -> 0 | K18: =+I18*0.09975 -> 0 | L18: =SUM(I18:K18) -> 0 | N18: =+L18-M18 -> 0
I19: =SUM(F19:H19) -> 0 | J19: =+I19*0.05 -> 0 | K19: =+I19*0.09975 -> 0 | L19: =SUM(I19:K19) -> 0 | N19: =+L19-M19 -> 0
I20: =SUM(F20:H20) -> 0 | J20: =+I20*0.05 -> 0 | K20: =+I20*0.09975 -> 0 | L20: =SUM(I20:K20) -> 0 | N20: =+L20-M20 -> 0
I21: =SUM(F21:H21) -> 0 | J21: =+I21*0.05 -> 0 | K21: =+I21*0.09975 -> 0 | L21: =SUM(I21:K21) -> 0 | N21: =+L21-M21 -> 0
I22: =SUM(F22:H22) -> 0 | J22: =+I22*0.05 -> 0 | K22: =+I22*0.09975 -> 0 | L22: =SUM(I22:K22) -> 0 | N22: =+L22-M22 -> 0
I23: =SUM(F23:H23) -> 0 | J23: =+I23*0.05 -> 0 | K23: =+I23*0.09975 -> 0 | L23: =SUM(I23:K23) -> 0 | N23: =+L23-M23 -> 0
I24: =SUM(F24:H24) -> 0 | J24: =+I24*0.05 -> 0 | K24: =+I24*0.09975 -> 0 | L24: =SUM(I24:K24) -> 0 | N24: =+L24-M24 -> 0
I25: =SUM(F25:H25) -> 0 | J25: =+I25*0.05 -> 0 | K25: =+I25*0.09975 -> 0 | L25: =SUM(I25:K25) -> 0 | N25: =+L25-M25 -> 0
I26: =SUM(F26:H26) -> 0 | J26: =+I26*0.05 -> 0 | K26: =+I26*0.09975 -> 0 | L26: =SUM(I26:K26) -> 0 | N26: =+L26-M26 -> 0
... I35: =SUM(F35:H35) -> 0 | J35: =+I35*0.05 -> 0 | K35: =+I35*0.09975 -> 0 | L35: =SUM(I35:K35) -> 0 | N35: =+L35-M35 -> 0
D36: =SUM(D4:D35) -> 35 | E36: =SUM(E4:E35) -> 1565 | F36: =SUM(F4:F35) -> 4462.5 | G36: =SUM(G4:G35) -> 98587.23 | H36: =SUM(H4:H35) -> 364 | I36: =SUM(I4:I35) -> 103413.73 | J36: =SUM(J4:J35) -> 5170.6865 | K36: =SUM(K4:K35) -> 10315.52 | ... N36: =SUM(N4:N35) -> 0 | O36: =SUM(O5:O35) -> 142000
E37: =+E36+D36 -> 1600

Sheet Société B
A1: Société B
A3: Date | B3: période | C3: facture | D3: Heures Associés | E3: Heures Employés | F3: Honoraires associés | G3: Honoraires employés | H3: Frais refacturables | I3: Sous-TOTAL | J3: TPS | K3: TVQ | L3: TOTAL | M3: payé | N3: dû | O3: Partage
A4: 44091 | B4: 1er mai au 1er août 2020 | C4: 20-2926 | D4: 41.75 | E4: =563.25-D4 -> 521.5 | F4: =125*D4 -> 5218.75 | G4: =28177.97-F4 -> 22959.22 | I4: =SUM(F4:H4) -> 28177.97 | J4: =+I4*0.05 -> 1408.8985 | K4: =+I4*0.09975 -> 2810.7525 | L4: =SUM(I4:K4) -> 32397.621 | M4: 32397.621 | N4: =+L4-M4 -> 0
A5: 44091 | B5: 2 au 29 août 2020 | C5: 20-2927 | D5: 8.5 | E5: =425-D5 -> 416.5 | F5: =125*D5 -> 1062.5 | G5: =19397.17-F5 -> 18334.67 | I5: =SUM(F5:H5) -> 19397.17 | J5: =+I5*0.05 -> 969.8585 | K5: =+I5*0.09975 -> 1934.8677 | L5: =SUM(I5:K5)-0.01 -> 22301.886 | M5: 22301.886 | N5: =+L5-M5 -> 0
A6: 44104 | B6: 30 août au 3 octbre 2020 | C6: 20-2945 | D6: 15.5 | E6: =625.5-D6 -> 610 | F6: =125*D6 -> 1937.5 | G6: =28006.02-F6 -> 26068.52 | H6: =1950+387.5+1540 -> 3877.5 | I6: =SUM(F6:H6) -> 31883.52 | J6: =+I6*0.05 -> 1594.176 | K6: =+I6*0.09975 -> 3180.3811 | L6: =SUM(I6:K6) -> 36658.077 | M6: 36658.077 | N6: =+L6-M6 -> 0 | O6: 37500
A7: 44145 | B7: 4 au 31 octobre 2020 | C7: 20-2968 | D7: 16.25 | E7: =682.75-D7 -> 666.5 | F7: =125*D7 -> 2031.25 | G7: =34562.58-F7+2499.88 -> 35031.21 | I7: =SUM(F7:H7) -> 37062.46 | J7: =+I7*0.05 -> 1853.123 | K7: =+I7*0.09975 -> 3696.9804 | L7: =SUM(I7:K7) -> 42612.563 | M7: 42612.563 | N7: =+L7-M7 -> 0
A8: 44172 | B8: 1er au 28 novembre 2020 | C8: 20-2984 | D8: 12.25 | E8: =64-D8 -> 51.75 | F8: =125*D8 -> 1531.25 | G8: =33250.76-F8 -> 31719.51 | I8: =SUM(F8:H8) -> 33250.76 | J8: =+I8*0.05 -> 1662.538 | K8: =+I8*0.09975 -> 3316.7633 | L8: =SUM(I8:K8) -> 38230.061 | M8: 38230.061 | N8: =+L8-M8 -> 0
A9: 44216 | B9: 29 novembre au 26 décembre 2020 | C9: 20-3008 | D9: 16 | E9: =744.5-D9 -> 728.5 | F9: =125*D9 -> 2000 | G9: =40933.39-F9 -> 38933.39 | I9: =SUM(F9:H9) -> 40933.39 | J9: =+I9*0.05 -> 2046.6695 | K9: =+I9*0.09975 -> 4083.1057 | L9: =SUM(I9:K9) -> 47063.165 | M9: 47063.165 | N9: =+L9-M9 -> 0
A10: 44244 | B10: 3 au 30 janvier 2021 | C10: 21-3029 | D10: 12 | E10: =823.5-D10 -> 811.5 | F10: =125*D10 -> 1500 | G10: =43929.39-F10 -> 42429.39 | I10: =SUM(F10:H10) -> 43929.39 | J10: =+I10*0.05 -> 2196.4695 | K10: =+I10*0.09975 -> 4381.9567 | L10: =SUM(I10:K10) -> 50507.816 | M10: 50507.816 | N10: =+L10-M10 -> 0
A11: 44265 | B11: 31 janvier au 27 février 2021 | C11: 21-3055 | D11: 11.25 | E11: =748.75-D11 -> 737.5 | F11: =125*D11 -> 1406.25 | G11: =39121.45-F11 -> 37715.2 | I11: =SUM(F11:H11) -> 39121.45 | J11: =+I11*0.05 -> 1956.0725 | K11: =+I11*0.09975 -> 3902.3646 | L11: =SUM(I11:K11) -> 44979.887 | M11: 44979.887 | N11: =+L11-M11 -> 0 | O11: 162500
A12: 44301 | B12: 28 février au 3 avril 2021 | C12: 21-3066 | D12: 9 | E12: =683-D12 -> 674 | F12: =125*D12 -> 1125 | G12: =34413.08-F12 -> 33288.08 | I12: =SUM(F12:H12) -> 34413.08 | J12: =+I12*0.05 -> 1720.654 | K12: =+I12*0.09975 -> 3432.7047 | L12: =SUM(I12:K12)-0.01 -> 39566.429 | M12: 39566.429 | N12: =+L12-M12 -> 0
A13: 44336 | B13: 4 avril au 1er mai 2021 | C13: 21-3116 | D13: 9.5 | E13: =476.75-D13 -> 467.25 | F13: =125*D13 -> 1187.5 | G13: =24696.18-F13 -> 23508.68 | I13: =SUM(F13:H13) -> 24696.18 | J13: =+I13*0.05 -> 1234.809 | K13: =+I13*0.09975 -> 2463.444 | L13: =SUM(I13:K13) -> 28394.433 | M13: 28394.433 | N13: =+L13-M13 -> 0
